<?xml version="1.0" encoding="utf-8"?>
<!-- This URDF was automatically created by SolidWorks to URDF Exporter! Originally created by Stephen Brawner (brawner@gmail.com) 
     Commit Version: 1.6.0-4-g7f85cfe  Build Version: 1.6.7995.38578
     For more information, please see http://wiki.ros.org/sw_urdf_exporter -->
<robot
  name="Xuanwu">
  <link
    name="base_link">
    <inertial>
      <origin
        xyz="0.000934 -0.004880 0.069827"
        rpy="0 0 0" />
      <mass
        value="2.016243" />
      <inertia
        ixx="0.020615"
        ixy="-0.000024"
        ixz="-0.000076"
        iyy="0.025088"
        iyz="0.000865"
        izz="0.006959" />
    </inertial>
    <visual>
      <origin
        xyz="0 0 0"
        rpy="0 0 0" />
      <geometry>
        <mesh
          filename="../meshes/base_link.STL" />
      </geometry>
      <material
        name="">
        <color
          rgba="1 1 1 1" />
      </material>
    </visual>
    <collision>
      <origin
        xyz="0 0 0.2"
        rpy="0 0 0" />
      <geometry>
        <box size="0.1 0.2 0.2"/>
      </geometry>
    </collision>
  </link>
  <link
    name="link_1">
    <inertial>
      <origin
        xyz="-0.006856 -0.062152 -0.076118"
        rpy="0 0 0" />
      <mass
        value="0.504" />
      <inertia
        ixx="0.006998"
        ixy="0.000002"
        ixz="0.000015"
        iyy="0.004490"
        iyz="-0.003216"
        izz="0.002973" />
    </inertial>
    <visual>
      <origin
        xyz="0 0 0"
        rpy="0 0 0" />
      <geometry>
        <mesh
          filename="../meshes/link_1.STL" />
      </geometry>
      <material
        name="">
        <color
          rgba="1 1 1 1" />
      </material>
    </visual>
    <!-- <collision>
      <origin
        xyz="0 0 0"
        rpy="0 0 0" />
      <geometry>
        <mesh
          filename="../meshes/link_1.STL" />
      </geometry>
    </collision> -->
  </link>
  <joint
    name="joint_1"
    type="revolute">
    <origin
      xyz="-0.073035 -1.4472E-05 -0.00095242"
      rpy="0 0 0" />
    <parent
      link="base_link" />
    <child
      link="link_1" />
    <axis
      xyz="0 0 1" />
    <limit
      lower="-0.5"
      upper="0.5"
      effort="7"
      velocity="12" />
  </joint>
  <link
    name="link_2">
    <inertial>
      <origin
        xyz="-0.000218 0.076679 0.000024"
        rpy="0 0 0" />
      <mass
        value="0.390" />
      <inertia
        ixx="0.002461"
        ixy="0.000007"
        ixz="0.000000"
        iyy="0.000116"
        iyz="-0.000001"
        izz="0.002479" />
    </inertial>
    <visual>
      <origin
        xyz="0 0 0"
        rpy="0 0 0" />
      <geometry>
        <mesh
          filename="../meshes/link_2.STL" />
      </geometry>
      <material
        name="">
        <color
          rgba="1 1 1 1" />
      </material>
    </visual>
    <!-- <collision>
      <origin
        xyz="0 0 0"
        rpy="0 0 0" />
      <geometry>
        <mesh
          filename="../meshes/link_2.STL" />
      </geometry>
    </collision> -->
  </link>
  <joint
    name="joint_2"
    type="revolute">
    <origin
      xyz="4.9294E-05 -0.083183 -0.11003"
      rpy="0 0 0" />
    <parent
      link="link_1" />
    <child
      link="link_2" />
    <axis
      xyz="0 1 0" />
    <limit
      lower="-0.7"
      upper="0.7"
      effort="7"
      velocity="12" />
  </joint>
  <link
    name="link_3">
    <inertial>
      <origin
        xyz="-0.000371 -0.000049 -0.144385"
        rpy="0 0 0" />
      <mass
        value="0.481" />
      <inertia
        ixx="0.011775"
        ixy="0.000000"
        ixz="-0.000059"
        iyy="0.011859"
        iyz="-0.000004"
        izz="0.000263" />
    </inertial>
    <visual>
      <origin
        xyz="0 0 0"
        rpy="0 0 0" />
      <geometry>
        <mesh
          filename="../meshes/link_3.STL" />
      </geometry>
      <material
        name="">
        <color
          rgba="1 1 1 1" />
      </material>
    </visual>
    <!-- <collision>
      <origin
        xyz="0 0 0"
        rpy="0 0 0" />
      <geometry>
        <mesh
          filename="../meshes/link_3.STL" />
      </geometry>
    </collision> -->
  </link>
  <joint
    name="joint_3"
    type="revolute">
    <origin
      xyz="0.00098795 0.082032 2.035E-05"
      rpy="0 0 0" />
    <parent
      link="link_2" />
    <child
      link="link_3" />
    <axis
      xyz="1 0 0" />
    <limit
      lower="-0.25"
      upper="1.57"
      effort="7"
      velocity="12" />
  </joint>
  <link
    name="link_4">
    <inertial>
      <origin
        xyz="-0.000371 0.000032 -0.144426"
        rpy="0 0 0" />
      <mass
        value="0.481" />
      <inertia
        ixx="0.011781"
        ixy="0.000000"
        ixz="-0.000059"
        iyy="0.011865"
        iyz="0.000002"
        izz="0.000263" />
    </inertial>
    <visual>
      <origin
        xyz="0 0 0"
        rpy="0 0 0" />
      <geometry>
        <mesh
          filename="../meshes/link_4.STL" />
      </geometry>
      <material
        name="">
        <color
          rgba="1 1 1 1" />
      </material>
    </visual>
    <!-- <collision>
      <origin
        xyz="0 0 0"
        rpy="0 0 0" />
      <geometry>
        <mesh
          filename="../meshes/link_4.STL" />
      </geometry>
    </collision> -->
  </link>
  <joint
    name="joint_4"
    type="revolute">
    <origin
      xyz="5E-05 -5.7742E-05 -0.17996"
      rpy="0 0 0" />
    <parent
      link="link_3" />
    <child
      link="link_4" />
    <axis
      xyz="1 0 0" />
    <limit
      lower="-1.57"
      upper="1.57"
      effort="7"
      velocity="12" />
  </joint>
  <link
    name="link_5">
    <inertial>
      <origin
        xyz="0.000400 -0.000014 -0.053536"
        rpy="0 0 0" />
      <mass
        value="0.122" />
      <inertia
        ixx="0.000567"
        ixy="0.000000"
        ixz="-0.000006"
        iyy="0.000555"
        iyz="0.000000"
        izz="0.000202" />
    </inertial>
    <visual>
      <origin
        xyz="0 0 0"
        rpy="0 0 0" />
      <geometry>
        <mesh
          filename="../meshes/link_5.STL" />
      </geometry>
      <material
        name="">
        <color
          rgba="1 1 1 1" />
      </material>
    </visual>
    <collision>
      <origin
        xyz="0 0 0"
        rpy="0 0 0" />
      <geometry>
        <mesh
          filename="../meshes/link_5.STL" />
      </geometry>
    </collision>
  </link>
  <joint
    name="joint_5"
    type="revolute">
    <origin
      xyz="5E-05 3.7392E-05 -0.18"
      rpy="0 0 0" />
    <parent
      link="link_4" />
    <child
      link="link_5" />
    <axis
      xyz="1 0 0" />
    <limit
      lower="-1.57"
      upper="1.57"
      effort="7"
      velocity="12" />
  </joint>
  <link
    name="link_6">
    <inertial>
      <origin
        xyz="0.006873 -0.062180 -0.076118"
        rpy="0 0 0" />
      <mass
        value="0.504" />
      <inertia
        ixx="0.007000"
        ixy="-0.000001"
        ixz="-0.000014"
        iyy="0.004490"
        iyz="-0.003218"
        izz="0.002974" />
    </inertial>
    <visual>
      <origin
        xyz="0 0 0"
        rpy="0 0 0" />
      <geometry>
        <mesh
          filename="../meshes/link_6.STL" />
      </geometry>
      <material
        name="">
        <color
          rgba="1 1 1 1" />
      </material>
    </visual>
    <!-- <collision>
      <origin
        xyz="0 0 0"
        rpy="0 0 0" />
      <geometry>
        <mesh
          filename="../meshes/link_6.STL" />
      </geometry>
    </collision> -->
  </link>
  <joint
    name="joint_6"
    type="revolute">
    <origin
      xyz="0.073035 1.4472E-05 -0.00095242"
      rpy="0 0 0" />
    <parent
      link="base_link" />
    <child
      link="link_6" />
    <axis
      xyz="0 0 1" />
    <limit
      lower="-0.5"
      upper="0.5"
      effort="7"
      velocity="12" />
  </joint>
  <link
    name="link_7">
    <inertial>
      <origin
        xyz="0.000189 0.076679 0.000046"
        rpy="0 0 0" />
      <mass
        value="0.390" />
      <inertia
        ixx="0.002461"
        ixy="-0.000006"
        ixz="0.000000"
        iyy="0.000116"
        iyz="-0.000001"
        izz="0.002479" />
    </inertial>
    <visual>
      <origin
        xyz="0 0 0"
        rpy="0 0 0" />
      <geometry>
        <mesh
          filename="../meshes/link_7.STL" />
      </geometry>
      <material
        name="">
        <color
          rgba="1 1 1 1" />
      </material>
    </visual>
    <!-- <collision>
      <origin
        xyz="0 0 0"
        rpy="0 0 0" />
      <geometry>
        <mesh
          filename="../meshes/link_7.STL" />
      </geometry>
    </collision> -->
  </link>
  <joint
    name="joint_7"
    type="revolute">
    <origin
      xyz="-2.035E-05 -0.083212 -0.11003"
      rpy="0 0 0" />
    <parent
      link="link_6" />
    <child
      link="link_7" />
    <axis
      xyz="0 1 0" />
    <limit
      lower="-0.7"
      upper="0.7"
      effort="7"
      velocity="12" />
  </joint>
  <link
    name="link_8">
    <inertial>
      <origin
        xyz="0.000371 -0.000021 -0.144414"
        rpy="0 0 0" />
      <mass
        value="0.481" />
      <inertia
        ixx="0.011779"
        ixy="0.000000"
        ixz="0.000059"
        iyy="0.011863"
        iyz="-0.000001"
        izz="0.000263" />
    </inertial>
    <visual>
      <origin
        xyz="0 0 0"
        rpy="0 0 0" />
      <geometry>
        <mesh
          filename="../meshes/link_8.STL" />
      </geometry>
      <material
        name="">
        <color
          rgba="1 1 1 1" />
      </material>
    </visual>
    <!-- <collision>
      <origin
        xyz="0 0 0"
        rpy="0 0 0" />
      <geometry>
        <mesh
          filename="../meshes/link_8.STL" />
      </geometry>
    </collision> -->
  </link>
  <joint
    name="joint_8"
    type="revolute">
    <origin
      xyz="-0.0010169 0.082032 4.9294E-05"
      rpy="0 0 0" />
    <parent
      link="link_7" />
    <child
      link="link_8" />
    <axis
      xyz="1 0 0" />
    <limit
      lower="-0.25"
      upper="1.57"
      effort="7"
      velocity="12" />
  </joint>
  <link
    name="link_9">
    <inertial>
      <origin
        xyz="0.000371 -0.000001 -0.144439"
        rpy="0 0 0" />
      <mass
        value="0.481" />
      <inertia
        ixx="0.011783"
        ixy="0.000000"
        ixz="0.000059"
        iyy="0.011867"
        iyz="0.000000"
        izz="0.000263" />
    </inertial>
    <visual>
      <origin
        xyz="0 0 0"
        rpy="0 0 0" />
      <geometry>
        <mesh
          filename="../meshes/link_9.STL" />
      </geometry>
      <material
        name="">
        <color
          rgba="1 1 1 1" />
      </material>
    </visual>
    <!-- <collision>
      <origin
        xyz="0 0 0"
        rpy="0 0 0" />
      <geometry>
        <mesh
          filename="../meshes/link_9.STL" />
      </geometry>
    </collision> -->
  </link>
  <joint
    name="joint_9"
    type="revolute">
    <origin
      xyz="-5E-05 -1.1901E-05 -0.17998"
      rpy="0 0 0" />
    <parent
      link="link_8" />
    <child
      link="link_9" />
    <axis
      xyz="1 0 0" />
    <limit
      lower="-1.57"
      upper="1.57"
      effort="7"
      velocity="12" />
  </joint>
  <link
    name="link_10">
    <inertial>
      <origin
        xyz="-0.000400 -0.000035 -0.053516"
        rpy="0 0 0" />
      <mass
        value="0.122" />
      <inertia
        ixx="0.000566"
        ixy="0.000000"
        ixz="0.000006"
        iyy="0.000554"
        iyz="0.000000"
        izz="0.000202" />
    </inertial>
    <visual>
      <origin
        xyz="0 0 0"
        rpy="0 0 0" />
      <geometry>
        <mesh
          filename="../meshes/link_10.STL" />
      </geometry>
      <material
        name="">
        <color
          rgba="1 1 1 1" />
      </material>
    </visual>
    <collision>
      <origin
        xyz="0 0 0"
        rpy="0 0 0" />
      <geometry>
        <mesh
          filename="../meshes/link_10.STL" />
      </geometry>
    </collision>
  </link>
  <joint
    name="joint_10"
    type="revolute">
    <origin
      xyz="-5E-05 1.1901E-05 -0.18002"
      rpy="0 0 0" />
    <parent
      link="link_9" />
    <child
      link="link_10" />
    <axis
      xyz="1 0 0" />
    <limit
      lower="-1.57"
      upper="1.57"
      effort="7"
      velocity="12" />
  </joint>
</robot>