<mujoco model="Xuanwu">
  <compiler angle="radian" meshdir="../meshes/"/>
  <size njmax="500" nconmax="100" />
  <option timestep="0.001" iterations="50" solver="PGS" gravity="0 0 0" noslip_iterations="20">
  </option>
  <default>
      <geom contype="1" conaffinity="1" condim="1" solref="0.005 1"/>
  </default>
  <visual>
      <quality shadowsize="4096"/>
      <global realtime="1"/>
  </visual>
  <asset>
    <texture name="texplane" type="2d" builtin="checker" rgb1=".2 .3 .4" rgb2=".1 0.15 0.2" width="512" height="512" mark="cross" markrgb=".8 .8 .8"/>
    <material name="matplane" reflectance="0." texture="texplane" texrepeat="1 1" texuniform="true"/>

    <mesh name="base_link" file="base_link.STL"/>
    <mesh name="link_1" file="link_1.STL"/>
    <mesh name="link_2" file="link_2.STL"/>
    <mesh name="link_3" file="link_3.STL"/>
    <mesh name="link_4" file="link_4.STL"/>
    <mesh name="link_5" file="link_5.STL"/>
    <mesh name="link_6" file="link_6.STL"/>
    <mesh name="link_7" file="link_7.STL"/>
    <mesh name="link_8" file="link_8.STL"/>
    <mesh name="link_9" file="link_9.STL"/>
    <mesh name="link_10" file="link_10.STL"/>
  </asset>

  <worldbody>
    <light directional="false" cutoff="60" exponent="1" diffuse=".5 .5 .5" specular=".1 .1 .1" pos="0.5 0.1 0.8" dir="-0.5 -0.1 -0.8"/>
    <geom name="ground" type="plane" size="0 0 1" pos="0.001 0 0" quat="1 0 0 0" material="matplane" condim="3" contype="15" conaffinity='0' friction="1.2 0.8 0.8"/>
    
    <body name="base_link" pos="0 0 1">
      <freejoint/>
      <site name="imu" pos="0 0 0"/>
      <inertial pos="0.001 0 0.07" mass="1.894" diaginertia="0.0154432 0.0102813 0.00634051"/>
      <geom type="mesh" group="1" density="0" rgba="1 1 1 1" mesh="base_link"/>
      <body name="link_1" pos="-0.073 0 -0.001" quat="1 0 0 0">
        <inertial pos="-0.007 -0.06 -0.073" mass="0.547" diaginertia="0.00246365 0.00239847 0.000392878"/>
        <joint name="joint_1" pos="0 0 0" axis="0 0 1" range="-0.5 0.5" actuatorfrcrange="-7 7" damping="0.01" frictionloss="0.01" armature="0.01"/>
        <geom type="mesh" group="1" density="0" rgba="1 1 1 1" mesh="link_1"/>
        <body name="link_2" pos="0 -0.083 -0.11" quat="1 0 0 0">
          <inertial pos="0 0.077 0" mass="0.378" diaginertia="0.000167 0.000152 0.000106"/>
          <joint name="joint_2" pos="0 0 0" axis="0 1 0" range="-0.7 0.7" actuatorfrcrange="-7 7" damping="0.01" frictionloss="0.01" armature="0.01"/>
          <geom type="mesh" group="1" density="0" rgba="1 1 1 1" mesh="link_2"/>
          <body name="link_3" pos="0 0.082 0" quat="1 0 0 0">
            <inertial pos="0 0 -0.1504" mass="0.436" diaginertia="0.001465 0.00140348 0.000206519"/>
            <joint name="joint_3" pos="0 0 0" axis="1 0 0" range="-0.25 1.57" actuatorfrcrange="-7 7" damping="0.01" frictionloss="0.01" armature="0.01"/>
            <geom type="mesh" group="1" density="0" rgba="1 1 1 1" mesh="link_3"/>
            <body name="link_4" pos="0 0 -0.18" quat="1 0 0 0">
              <inertial pos="0 0 -0.1504" mass="0.436" diaginertia="0.001465 0.00140348 0.000206519"/>
              <joint name="joint_4" pos="0 0 0" axis="1 0 0" range="-1.57 1.57" actuatorfrcrange="-7 7" damping="0.01" frictionloss="0.01" armature="0.01"/>
              <geom type="mesh" group="1" density="0" rgba="1 1 1 1" mesh="link_4"/>
              <body name="link_5" pos="0 0 -0.18" quat="1 0 0 0">
                <inertial pos="0 0 -0.053" mass="0.105" diaginertia="0.000215679 0.000197321 0.000197"/>
                <joint name="joint_5" pos="0 0 0" axis="1 0 0" range="-1.57 1.57" actuatorfrcrange="-7 7" damping="0.01" frictionloss="0.01" armature="0.01"/>
                <geom type="mesh" group="1" density="0" rgba="1 1 1 1" mesh="link_5"/>
              </body>
            </body>
          </body>
        </body>
      </body>
      <body name="link_6" pos="0.073 0 -0.001" quat="1 0 0 0">
        <inertial pos="0.007 -0.06 -0.074" mass="0.547" diaginertia="0.00246307 0.00239882 0.000393103"/>
        <joint name="joint_6" pos="0 0 0" axis="0 0 1" range="-0.5 0.5" actuatorfrcrange="-7 7" damping="0.01" frictionloss="0.01" armature="0.01"/>
        <geom type="mesh" group="1" density="0" rgba="1 1 1 1" mesh="link_6"/>
        <body name="link_7" pos="0 -0.083 -0.11" quat="1 0 0 0">
          <inertial pos="0 0.077 0" mass="0.378" diaginertia="0.000167 0.000152 0.000106"/>
          <joint name="joint_7" pos="0 0 0" axis="0 1 0" range="-0.7 0.7" actuatorfrcrange="-7 7" damping="0.01" frictionloss="0.01" armature="0.01"/>
          <geom type="mesh" group="1" density="0" rgba="1 1 1 1" mesh="link_7"/>
          <body name="link_8" pos="0 0.082 0" quat="1 0 0 0"> 
            <inertial pos="0 0 -0.1504" mass="0.436" diaginertia="0.001465 0.00140348 0.000206519"/>
            <joint name="joint_8" pos="0 0 0" axis="1 0 0" range="-0.25 1.57" actuatorfrcrange="-7 7" damping="0.01" frictionloss="0.01" armature="0.01"/>
            <geom type="mesh" group="1" density="0" rgba="1 1 1 1" mesh="link_8"/>
            <body name="link_9" pos="0 0 -0.18" quat="1 0 0 0">
              <inertial pos="0 0 -0.1504" mass="0.436" diaginertia="0.001465 0.00140348 0.000206519"/>
              <joint name="joint_9" pos="0 0 0" axis="1 0 0" range="-1.57 1.57" actuatorfrcrange="-7 7" damping="0.01" frictionloss="0.01" armature="0.01"/>
              <geom type="mesh" group="1" density="0" rgba="1 1 1 1" mesh="link_9"/>
              <body name="link_10" pos="0 0 -0.18" quat="1 0 0 0">
                <inertial pos="0 0 -0.053" mass="0.105" diaginertia="0.000215679 0.000197321 0.000197"/>
                <joint name="joint_10" pos="0 0 0" axis="1 0 0" range="-1.57 1.57" actuatorfrcrange="-7 7" damping="0.01" frictionloss="0.01" armature="0.01"/>
                <geom type="mesh" group="1" density="0" rgba="1 1 1 1" mesh="link_10"/>
              </body>
            </body>
          </body>
        </body>
      </body>
    </body>
  </worldbody>
  <actuator>
    <motor gear="1" joint="joint_1" name="motor_1" ctrllimited="true"  ctrlrange='-7 7'/>
    <motor gear="1" joint="joint_2" name="motor_2" ctrllimited="true"  ctrlrange='-7 7'/>
    <motor gear="1" joint="joint_3" name="motor_3" ctrllimited="true"  ctrlrange='-7 7'/>
    <motor gear="1" joint="joint_4" name="motor_4" ctrllimited="true"  ctrlrange='-7 7'/>
    <motor gear="1" joint="joint_5" name="motor_5" ctrllimited="true"  ctrlrange='-7 7'/>
    <motor gear="1" joint="joint_6" name="motor_6" ctrllimited="true"  ctrlrange='-7 7'/>
    <motor gear="1" joint="joint_7" name="motor_7" ctrllimited="true"  ctrlrange='-7 7'/>
    <motor gear="1" joint="joint_8" name="motor_8" ctrllimited="true"  ctrlrange='-7 7'/>
    <motor gear="1" joint="joint_9" name="motor_9" ctrllimited="true"  ctrlrange='-7 7'/>
    <motor gear="1" joint="joint_10" name="motor_10" ctrllimited="true"  ctrlrange='-7 7'/>
  </actuator>
  <sensor>
    <jointpos name="joint_1_pos" joint="joint_1"/>
    <jointpos name="joint_2_pos" joint="joint_2"/>
    <jointpos name="joint_3_pos" joint="joint_3"/>
    <jointpos name="joint_4_pos" joint="joint_4"/>
    <jointpos name="joint_5_pos" joint="joint_5"/>
    <jointpos name="joint_6_pos" joint="joint_6"/>
    <jointpos name="joint_7_pos" joint="joint_7"/>
    <jointpos name="joint_8_pos" joint="joint_8"/>
    <jointpos name="joint_9_pos" joint="joint_9"/>
    <jointpos name="joint_10_pos" joint="joint_10"/>
    <jointvel name="joint_1_vel" joint="joint_1"/>
    <jointvel name="joint_2_vel" joint="joint_2"/>
    <jointvel name="joint_3_vel" joint="joint_3"/>
    <jointvel name="joint_4_vel" joint="joint_4"/>
    <jointvel name="joint_5_vel" joint="joint_5"/>
    <jointvel name="joint_6_vel" joint="joint_6"/>
    <jointvel name="joint_7_vel" joint="joint_7"/>
    <jointvel name="joint_8_vel" joint="joint_8"/>
    <jointvel name="joint_9_vel" joint="joint_9"/>
    <jointvel name="joint_10_vel" joint="joint_10"/>
    <accelerometer name="body_acc" site="imu"/>
    <velocimeter name="body_vel" site="imu"/>
    <gyro name="body_gyro" site="imu"/>
    <framepos name="body_pos" objtype="site" objname="imu"/>
    <framequat name="body_quat" objtype="site" objname="imu"/>
  </sensor>
</mujoco>
