<mujoco model="Xuanwu">
  <compiler angle="radian" meshdir="../meshes/"/>
  <size njmax="500" nconmax="100" />
  <option timestep="0.001" iterations="50" solver="PGS" gravity="0 0 -9.81" noslip_iterations="20">
  </option>
  <default>
      <geom contype="1" conaffinity="1" condim="1" solref="0.005 1"/>
  </default>
  <visual>
      <quality shadowsize="4096"/>
      <global realtime="1"/>
  </visual>
  <asset>
    <texture name="texplane" type="2d" builtin="checker" rgb1=".2 .3 .4" rgb2=".1 0.15 0.2" width="512" height="512" mark="cross" markrgb=".8 .8 .8"/>
    <material name="matplane" reflectance="0." texture="texplane" texrepeat="1 1" texuniform="true"/>

    <mesh name="base_link" file="base_link.STL"/>
    <mesh name="link_1" file="link_1.STL"/>
    <mesh name="link_2" file="link_2.STL"/>
    <mesh name="link_3" file="link_3.STL"/>
    <mesh name="link_4" file="link_4.STL"/>
    <mesh name="link_5" file="link_5.STL"/>
    <mesh name="link_6" file="link_6.STL"/>
    <mesh name="link_7" file="link_7.STL"/>
    <mesh name="link_8" file="link_8.STL"/>
    <mesh name="link_9" file="link_9.STL"/>
    <mesh name="link_10" file="link_10.STL"/>
  </asset>

  <worldbody>
    <light directional="false" cutoff="60" exponent="1" diffuse=".5 .5 .5" specular=".1 .1 .1" pos="0.5 0.1 0.8" dir="-0.5 -0.1 -0.8"/>
    <geom name="ground" type="plane" size="0 0 1" pos="0.001 0 0" quat="1 0 0 0" material="matplane" condim="3" contype="15" conaffinity='0' friction="1.2 0.8 0.8"/>
    
    <body name="base_link" pos="0 0 0">
      <freejoint/>
      <inertial pos="0.001 0 0.07" mass="1.894" diaginertia="0.01 0.015 0.006"/>
      <geom type="mesh" contype="0" conaffinity="0" group="1" density="0" rgba="1 1 1 1" mesh="base_link"/>
      <geom size="0.1 0.15 0.15" pos="0.001 0 0.07" type="box" rgba="1 1 1 0" />
      <body name="link_1">
        <inertial pos="-0.08 -0.06 -0.074" quat="0.680193 -0.193229 0.193229 0.680193" mass="0.547" diaginertia="0.00166667 0.00166667 0.00166667"/>
        <joint name="joint_1" pos="0 0 0" axis="0 0 1" range="-0.5 0.5" actuatorfrcrange="-7 7"/>
        <geom type="mesh" contype="0" conaffinity="0" group="1" density="0" rgba="1 1 1 1" mesh="link_1"/>
        <geom type="mesh" rgba="0.69804 0.69804 0.69804 1" mesh="link_1"/>
        <body name="link_2">
          <inertial pos="-0.073 -0.006 -0.111" mass="0.378" diaginertia="0.0001 0.0001 0.0001"/>
          <joint name="joint_2" pos="0 0 0" axis="0 1 0" range="-0.7 0.7" actuatorfrcrange="-7 7"/>
          <geom type="mesh" contype="0" conaffinity="0" group="1" density="0" rgba="1 1 1 1" mesh="link_2"/>
          <geom type="mesh" rgba="0.69804 0.69804 0.69804 1" mesh="link_2"/>
          <body name="link_3">
            <inertial pos="-0.072 -0.001 -0.261" mass="0.436" diaginertia="0.001 0.001 0.0001"/>
            <joint name="joint_3" pos="0 0 0" axis="1 0 0" range="-0.25 1.57" actuatorfrcrange="-7 7"/>
            <geom type="mesh" contype="0" conaffinity="0" group="1" density="0" rgba="1 1 1 1" mesh="link_3"/>
            <geom type="mesh" rgba="0.698039 0.698039 0.698039 1" mesh="link_3"/>
            <body name="link_4">
              <inertial pos="-0.072 -0.001 -0.441" mass="0.436" diaginertia="0.001 0.001 0.0001"/>
              <joint name="joint_4" pos="0 0 0" axis="1 0 0" range="-1.57 1.57" actuatorfrcrange="-7 7"/>
              <geom type="mesh" contype="0" conaffinity="0" group="1" density="0" rgba="1 1 1 1" mesh="link_4"/>
              <geom type="mesh" rgba="0.698039 0.698039 0.698039 1" mesh="link_4"/>
              <body name="link_5">
                <inertial pos="-0.071 -0.001 -0.524" mass="0.105" diaginertia="0.0001 0.0001 0.0001"/>
                <joint name="joint_5" pos="0 0 0" axis="1 0 0" range="-1.57 1.57" actuatorfrcrange="-7 7"/>
                <geom type="mesh" contype="0" conaffinity="0" group="1" density="0" rgba="1 1 1 1" mesh="link_5"/>
                <geom type="mesh" rgba="0.698039 0.698039 0.698039 1" mesh="link_5"/>
              </body>
            </body>
          </body>
        </body>
      </body>
      <body name="link_6">
        <inertial pos="0.08 -0.06 -0.074" quat="0.680193 -0.193229 0.193229 0.680193" mass="0.547" diaginertia="0.00166667 0.00166667 0.00166667"/>
        <joint name="joint_6" pos="0 0 0" axis="0 0 1" range="-0.5 0.5" actuatorfrcrange="-7 7"/>
        <geom type="mesh" contype="0" conaffinity="0" group="1" density="0" rgba="1 1 1 1" mesh="link_6"/>
        <geom type="mesh" rgba="0.698039 0.698039 0.698039 1" mesh="link_6"/>
        <body name="link_7">
          <inertial pos="0.073 -0.006 -0.111" mass="0.378" diaginertia="0.0001 0.0001 0.0001"/>
          <joint name="joint_7" pos="0 0 0" axis="0 1 0" range="-0.7 0.7" actuatorfrcrange="-7 7"/>
          <geom type="mesh" contype="0" conaffinity="0" group="1" density="0" rgba="1 1 1 1" mesh="link_7"/>
          <geom type="mesh" rgba="1 1 1 1" mesh="link_7"/>
          <body name="link_8">
            <inertial pos="0.072 -0.001 -0.261" mass="0.436" diaginertia="0.001 0.001 0.0001"/>
            <joint name="joint_8" pos="0 0 0" axis="1 0 0" range="-0.25 1.57" actuatorfrcrange="-7 7"/>
            <geom type="mesh" contype="0" conaffinity="0" group="1" density="0" rgba="1 1 1 1" mesh="link_8"/>
            <geom type="mesh" rgba="0.698039 0.698039 0.698039 1" mesh="link_8"/>
            <body name="link_9">
              <inertial pos="0.072 -0.001 -0.441" mass="0.436" diaginertia="0.001 0.001 0.0001"/>
              <joint name="joint_9" pos="0 0 0" axis="1 0 0" range="-1.57 1.57" actuatorfrcrange="-7 7"/>
              <geom type="mesh" contype="0" conaffinity="0" group="1" density="0" rgba="1 1 1 1" mesh="link_9"/>
              <geom type="mesh" rgba="0.698039 0.698039 0.698039 1" mesh="link_9"/>
              <body name="link_10">
                <inertial pos="0.071 -0.001 -0.524" mass="0.105" diaginertia="0.0001 0.0001 0.0001"/>
                <joint name="joint_10" pos="0 0 0" axis="1 0 0" range="-1.57 1.57" actuatorfrcrange="-7 7"/>
                <geom type="mesh" contype="0" conaffinity="0" group="1" density="0" rgba="1 1 1 1" mesh="link_10"/>
                <geom type="mesh" rgba="0.698039 0.698039 0.698039 1" mesh="link_10"/>
              </body>
            </body>
          </body>
        </body>
      </body>
    </body>
  </worldbody>
</mujoco>
